#VRML_SIM R2020a utf8
WorldInfo {
}
Robot {
  translation 0.2 0.06 0.2
  rotation 0.00036331034961334445 0.9999995614464774 0.0008631989589741182 -2.3240471614611904
  children [
    DEF CAM HingeJoint {
      endPoint Solid {
        rotation 0 1 0 3.141592653589793
        children [
          Transform {
            translation 0 0.01 0
            rotation 1 0 0 -1.5707996938995747
            children [
              Shape {
                appearance MattePaint {
                }
                geometry Cylinder {
                  height 0.03
                  radius 0.01
                }
              }
            ]
          }
          Camera {
            translation 0 0.02 0
            rotation 1 0 0 0
            name "CAM"
          }
        ]
        name "solid(1)"
      }
    }
    DEF BODY Group {
      children [
        DEF markerfix Transform {
          children [
            Shape {
              appearance MattePaint {
                baseColor 0 0 0
              }
              geometry Cylinder {
                height 0.1
                radius 0.01
              }
            }
          ]
        }
        DEF marker Transform {
          translation 0 0.07 0
          children [
            Shape {
              appearance GlossyPaint {
                baseColor 1 0 0.498039
              }
              geometry Cylinder {
                height 0.05
                radius 0.02
              }
            }
          ]
        }
        DEF main Transform {
          translation 0 -0.03 0
          children [
            Shape {
              appearance MattePaint {
                baseColor 0 0 0.498039
              }
              geometry Cylinder {
                height 0.05
                radius 0.05
              }
            }
          ]
        }
        DEF front Transform {
          translation 0 -0.0545 -0.04
          children [
            Shape {
              appearance MattePaint {
                baseColor 0 0 0
              }
              geometry Cylinder {
                height 0.01
                radius 0.01
              }
            }
          ]
        }
        DEF back Transform {
          translation 0 -0.0545 0.04
          children [
            Shape {
              appearance MattePaint {
                baseColor 0 0 0
              }
              geometry Cylinder {
                height 0.01
                radius 0.01
              }
            }
          ]
        }
      ]
    }
    HingeJoint {
      jointParameters HingeJointParameters {
        position 2.411195383723881
        anchor -0.05 -0.04 0
      }
      device [
        RotationalMotor {
          name "left wheel motor"
        }
      ]
      endPoint Solid {
        translation -0.05999871748116081 -0.04000489498144871 1.205709154068918e-05
        rotation 0.9999999999999977 2.2467935343468908e-08 -6.47294716581437e-08 2.4111952272869566
        children [
          DEF WHEEL Transform {
            rotation 0 0 1 1.5707996938995747
            children [
              Shape {
                appearance MattePaint {
                  baseColor 0 0 0
                }
                geometry Cylinder {
                  height 0.02
                  radius 0.02
                  subdivision 24
                }
              }
            ]
          }
        ]
        boundingObject USE WHEEL
        physics Physics {
        }
      }
    }
    HingeJoint {
      jointParameters HingeJointParameters {
        position 2.186986912110353
        anchor 0.05 -0.04 0
      }
      device [
        RotationalMotor {
          name "right wheel motor"
          acceleration 6
        }
      ]
      endPoint Solid {
        translation 0.06000128159021598 -0.040002683391633605 1.1143981457536344e-05
        rotation 0.9999999999999961 -7.787788308787006e-08 4.0440553447249064e-08 2.186986758291521
        children [
          DEF WHEEL Transform {
            rotation 0 0 1 1.5707996938995747
            children [
              Shape {
                appearance MattePaint {
                  baseColor 0 0 0
                }
                geometry Cylinder {
                  height 0.02
                  radius 0.02
                  subdivision 24
                }
              }
            ]
          }
        ]
        boundingObject USE WHEEL
        physics Physics {
        }
      }
    }
  ]
  name "Raspi"
  boundingObject USE BODY
  physics Physics {
    density -1
    mass 1
  }
  controller "raspi"
}
Robot {
  translation -0.2 0.06 -0.2
  rotation -0.0016325959650545449 0.9999984152482045 0.0007100221790025864 0.8014664204637744
  children [
    DEF CAM HingeJoint {
      endPoint Solid {
        rotation 0 1 0 3.141592653589793
        children [
          Transform {
            translation 0 0.01 0
            rotation 1 0 0 -1.5707996938995747
            children [
              Shape {
                appearance MattePaint {
                }
                geometry Cylinder {
                  height 0.03
                  radius 0.01
                }
              }
            ]
          }
          Camera {
            translation 0 0.02 0
            rotation 1 0 0 0
            name "CAM"
          }
        ]
        name "solid(1)"
      }
    }
    DEF BODY Group {
      children [
        DEF markerfix Transform {
          children [
            Shape {
              appearance MattePaint {
                baseColor 0 0 0
              }
              geometry Cylinder {
                height 0.1
                radius 0.01
              }
            }
          ]
        }
        DEF marker Transform {
          translation 0 0.07 0
          children [
            Shape {
              appearance MattePaint {
                baseColor 1 0 0.498039
              }
              geometry Cylinder {
                height 0.05
                radius 0.02
              }
            }
          ]
        }
        DEF main Transform {
          translation 0 -0.03 0
          children [
            Shape {
              appearance MattePaint {
                baseColor 0 0 0.498039
              }
              geometry Cylinder {
                height 0.05
                radius 0.05
              }
            }
          ]
        }
        DEF front Transform {
          translation 0 -0.0545 -0.04
          children [
            Shape {
              appearance MattePaint {
                baseColor 0 0 0
              }
              geometry Cylinder {
                height 0.01
                radius 0.01
              }
            }
          ]
        }
        DEF back Transform {
          translation 0 -0.0545 0.04
          children [
            Shape {
              appearance MattePaint {
                baseColor 0 0 0
              }
              geometry Cylinder {
                height 0.01
                radius 0.01
              }
            }
          ]
        }
      ]
    }
    HingeJoint {
      jointParameters HingeJointParameters {
        position 0.2411203565411699
        anchor -0.05 -0.04 0
      }
      device [
        RotationalMotor {
          name "left wheel motor"
        }
      ]
      endPoint Solid {
        translation -0.05999871748116081 -0.039987282945298096 -2.758771377371709e-06
        rotation 0.9999999999998584 -3.630937795712627e-07 -3.8901746476882167e-07 0.241120200104278
        children [
          DEF WHEEL Transform {
            rotation 0 0 1 1.5707996938995747
            children [
              Shape {
                appearance MattePaint {
                  baseColor 0 0 0
                }
                geometry Cylinder {
                  height 0.02
                  radius 0.02
                  subdivision 24
                }
              }
            ]
          }
        ]
        name "solid(2)"
        boundingObject USE WHEEL
        physics Physics {
        }
      }
    }
    HingeJoint {
      jointParameters HingeJointParameters {
        position 0.1290153431213211
        anchor 0.05 -0.04 0
      }
      device [
        RotationalMotor {
          name "right wheel motor"
          acceleration 6
        }
      ]
      endPoint Solid {
        translation 0.06000128159021598 -0.03998889634285878 -2.8456478129683024e-06
        rotation 0.9999999999992555 -7.665268879987207e-08 1.217873018484846e-06 0.129015187884867
        children [
          DEF WHEEL Transform {
            rotation 0 0 1 1.5707996938995747
            children [
              Shape {
                appearance MattePaint {
                  baseColor 0 0 0
                }
                geometry Cylinder {
                  height 0.02
                  radius 0.02
                  subdivision 24
                }
              }
            ]
          }
        ]
        boundingObject USE WHEEL
        physics Physics {
        }
      }
    }
  ]
  name "Raspi(1)"
  boundingObject USE BODY
  physics Physics {
    density -1
    mass 1
  }
  controller ""
}
Viewpoint {
  orientation 0.2911682146813767 0.8948485048496391 0.33833005206103867 4.926689998038938
  position -1.548640475368361 1.0535305343643726 0.4396302781204986
}
RectangleArena {
  floorAppearance Appearance {
    texture ImageTexture {
      url [
        "C:/Temp/Spielfeld_01.png"
      ]
      repeatS FALSE
      repeatT FALSE
    }
    textureTransform TextureTransform {
      scale 0.5 0.5
    }
  }
  wallAppearance MattePaint {
  }
}
TexturedBackground {
}
