#VRML_SIM R2020a utf8
WorldInfo {
}
Robot {
  translation 0.2 0.0595916 0.2
  rotation 0 1 0 -2.3487896938995747
  children [
    Camera {
      translation 0 -0.04 0
      rotation 1 0 0 -1.5707996938995747
      scale 0.1 0.1 0.1
      name "floor_camera"
      width 1
      height 1
    }
    PointLight {
      attenuation 0 0 1
      location 0 0.3 0
    }
    DistanceSensor {
      translation 0 -0.03 0.05
      rotation 0 1 0 -1.5708003061004252
      lookupTable [
        0 0 0
        0.2 1000 0
      ]
      gaussianWidth 2
    }
    DEF tLED Transform {
      translation 0 -0.03 0.05
      children [
        LED {
          scale 0.1 0.1 0.1
          children [
            Shape {
              appearance PBRAppearance {
                baseColor 0.8 0.8 0.8
                roughness 0.2
                metalness 0.5
                emissiveIntensity 100
              }
              geometry Box {
                size 0.1 0.1 0.1
              }
            }
          ]
          name "stateled"
          color []
          gradual TRUE
        }
      ]
    }
    DEF CAM HingeJoint {
      endPoint Solid {
        rotation 0 1 0 3.141592653589793
        children [
          Transform {
            translation 0 0.01 0
            rotation 1 0 0 -1.5707996938995747
            children [
              Shape {
                appearance MattePaint {
                }
                geometry Cylinder {
                  height 0.03
                  radius 0.01
                }
              }
            ]
          }
          Camera {
            translation 0 0.02 0
            rotation 1 0 0 0
            name "CAM"
          }
        ]
        name "solid(1)"
      }
    }
    DEF BODY Group {
      children [
        DEF markerfix Transform {
          children [
            Shape {
              appearance MattePaint {
                baseColor 0 0 0
              }
              geometry Cylinder {
                height 0.1
                radius 0.01
              }
            }
          ]
        }
        DEF marker Transform {
          translation 0 0.07 0
          children [
            Shape {
              appearance GlossyPaint {
                baseColor 1 0 0.498039
              }
              geometry Cylinder {
                height 0.05
                radius 0.02
              }
            }
          ]
        }
        DEF main Transform {
          translation 0 -0.03 0
          children [
            Shape {
              appearance MattePaint {
                baseColor 0 0 0.498039
              }
              geometry Cylinder {
                height 0.05
                radius 0.05
              }
            }
          ]
        }
        DEF front Transform {
          translation 0 -0.0545 -0.04
          children [
            Shape {
              appearance MattePaint {
                baseColor 0 0 0
              }
              geometry Cylinder {
                height 0.01
                radius 0.01
              }
            }
          ]
        }
        DEF back Transform {
          translation 0 -0.0545 0.04
          children [
            Shape {
              appearance MattePaint {
                baseColor 0 0 0
              }
              geometry Cylinder {
                height 0.01
                radius 0.01
              }
            }
          ]
        }
      ]
    }
    HingeJoint {
      jointParameters HingeJointParameters {
        position 28.555849030474334
        anchor -0.05 -0.04 0
      }
      device [
        RotationalMotor {
          name "left wheel motor"
        }
      ]
      endPoint Solid {
        translation -0.05999871748116081 -0.04001281809034496 2.2429578043810503e-06
        rotation 0.999999999999998 4.6538820200857015e-08 -4.171101426378803e-08 3.423107650506266
        children [
          DEF WHEEL Transform {
            rotation 0 0 1 1.5707996938995747
            children [
              Shape {
                appearance MattePaint {
                  baseColor 0 0 0
                }
                geometry Cylinder {
                  height 0.02
                  radius 0.02
                  subdivision 24
                }
              }
            ]
          }
        ]
        boundingObject USE WHEEL
        physics Physics {
        }
      }
    }
    HingeJoint {
      jointParameters HingeJointParameters {
        position 16.716107244222684
        anchor 0.05 -0.04 0
      }
      device [
        RotationalMotor {
          name "right wheel motor"
          acceleration 6
        }
      ]
      endPoint Solid {
        translation 0.06000128159021598 -0.04000927383303133 -6.7368341446278985e-06
        rotation 0.9999999999999963 -7.507035050209038e-08 -4.1247439173153065e-08 4.149736481851264
        children [
          DEF WHEEL Transform {
            rotation 0 0 1 1.5707996938995747
            children [
              Shape {
                appearance MattePaint {
                  baseColor 0 0 0
                }
                geometry Cylinder {
                  height 0.02
                  radius 0.02
                  subdivision 24
                }
              }
            ]
          }
        ]
        boundingObject USE WHEEL
        physics Physics {
        }
      }
    }
  ]
  name "Raspi"
  boundingObject USE BODY
  physics Physics {
    density -1
    mass 1
  }
  controller "raspi"
}
Viewpoint {
  orientation -0.21837548433849704 -0.9228134428346874 -0.3173759561837004 2.010139016572825
  position -1.4879597424038324 1.3161496149243896 -0.8013921437621927
}
RectangleArena {
  floorAppearance Appearance {
    texture ImageTexture {
      url [
        "C:/Temp/Spielfeld_01.png"
      ]
      repeatS FALSE
      repeatT FALSE
    }
    textureTransform TextureTransform {
      scale 0.5 0.5
    }
  }
  wallAppearance MattePaint {
  }
}
Robot {
  translation -0.2 0.0595916 -0.2
  rotation 0 1 0 0.7853996938995746
  children [
    Camera {
      translation 0 -0.04 0
      rotation 1 0 0 -1.5707996938995747
      scale 0.1 0.1 0.1
      name "floor_camera"
      width 1
      height 1
    }
    PointLight {
      attenuation 0 0 1
      location 0 0.3 0
    }
    DistanceSensor {
      translation 0 -0.03 0.05
      rotation 0 1 0 -1.5708003061004252
      lookupTable [
        0 0 0
        0.2 1000 0
      ]
      gaussianWidth 2
    }
    DEF tLED Transform {
      translation 0 -0.03 0.05
      children [
        LED {
          scale 0.1 0.1 0.1
          children [
            Shape {
              appearance PBRAppearance {
                baseColor 0.8 0.8 0.8
                roughness 0.2
                metalness 0.5
                emissiveIntensity 100
              }
              geometry Box {
                size 0.1 0.1 0.1
              }
            }
          ]
          name "stateled"
          color []
          gradual TRUE
        }
      ]
    }
    DEF CAM HingeJoint {
      endPoint Solid {
        rotation 0 1 0 3.141592653589793
        children [
          Transform {
            translation 0 0.01 0
            rotation 1 0 0 -1.5707996938995747
            children [
              Shape {
                appearance MattePaint {
                }
                geometry Cylinder {
                  height 0.03
                  radius 0.01
                }
              }
            ]
          }
          Camera {
            translation 0 0.02 0
            rotation 1 0 0 0
            name "CAM"
          }
        ]
        name "solid(1)"
      }
    }
    DEF BODY Group {
      children [
        DEF markerfix Transform {
          children [
            Shape {
              appearance MattePaint {
                baseColor 0 0 0
              }
              geometry Cylinder {
                height 0.1
                radius 0.01
              }
            }
          ]
        }
        DEF marker Transform {
          translation 0 0.07 0
          children [
            Shape {
              appearance GlossyPaint {
                baseColor 1 0 0.498039
              }
              geometry Cylinder {
                height 0.05
                radius 0.02
              }
            }
          ]
        }
        DEF main Transform {
          translation 0 -0.03 0
          children [
            Shape {
              appearance MattePaint {
                baseColor 0 0 0.498039
              }
              geometry Cylinder {
                height 0.05
                radius 0.05
              }
            }
          ]
        }
        DEF front Transform {
          translation 0 -0.0545 -0.04
          children [
            Shape {
              appearance MattePaint {
                baseColor 0 0 0
              }
              geometry Cylinder {
                height 0.01
                radius 0.01
              }
            }
          ]
        }
        DEF back Transform {
          translation 0 -0.0545 0.04
          children [
            Shape {
              appearance MattePaint {
                baseColor 0 0 0
              }
              geometry Cylinder {
                height 0.01
                radius 0.01
              }
            }
          ]
        }
      ]
    }
    HingeJoint {
      jointParameters HingeJointParameters {
        position 28.555849030474334
        anchor -0.05 -0.04 0
      }
      device [
        RotationalMotor {
          name "left wheel motor"
        }
      ]
      endPoint Solid {
        translation -0.05999871748116081 -0.04001281809034496 2.2429578043810503e-06
        rotation 0.999999999999998 4.6538820200857015e-08 -4.171101426378803e-08 3.423107650506266
        children [
          DEF WHEEL Transform {
            rotation 0 0 1 1.5707996938995747
            children [
              Shape {
                appearance MattePaint {
                  baseColor 0 0 0
                }
                geometry Cylinder {
                  height 0.02
                  radius 0.02
                  subdivision 24
                }
              }
            ]
          }
        ]
        name "solid(2)"
        boundingObject USE WHEEL
        physics Physics {
        }
      }
    }
    HingeJoint {
      jointParameters HingeJointParameters {
        position 16.716107244222684
        anchor 0.05 -0.04 0
      }
      device [
        RotationalMotor {
          name "right wheel motor"
          acceleration 6
        }
      ]
      endPoint Solid {
        translation 0.06000128159021598 -0.04000927383303133 -6.7368341446278985e-06
        rotation 0.9999999999999963 -7.507035050209038e-08 -4.1247439173153065e-08 4.149736481851264
        children [
          DEF WHEEL Transform {
            rotation 0 0 1 1.5707996938995747
            children [
              Shape {
                appearance MattePaint {
                  baseColor 0 0 0
                }
                geometry Cylinder {
                  height 0.02
                  radius 0.02
                  subdivision 24
                }
              }
            ]
          }
        ]
        boundingObject USE WHEEL
        physics Physics {
        }
      }
    }
  ]
  name "Raspi(2)"
  boundingObject USE BODY
  physics Physics {
    density -1
    mass 1
  }
  controller ""
}
TexturedBackground {
}
