#VRML_SIM R2020a utf8
WorldInfo {
}
Robot {
  translation 0.2 0.06 0.2
  children [
    DEF BODY Group {
      children [
        DEF main Transform {
          translation 0 -0.03 0
          children [
            Shape {
              appearance MattePaint {
                baseColor 0 0 0.498039
              }
              geometry Cylinder {
                height 0.05
                radius 0.05
              }
            }
          ]
        }
        DEF front Transform {
          translation 0 -0.0545 -0.04
          children [
            Shape {
              appearance MattePaint {
                baseColor 0 0 0
              }
              geometry Cylinder {
                height 0.01
                radius 0.01
              }
            }
          ]
        }
        DEF back Transform {
          translation 0 -0.0545 0.04
          children [
            Shape {
              appearance MattePaint {
                baseColor 0 0 0
              }
              geometry Cylinder {
                height 0.01
                radius 0.01
              }
            }
          ]
        }
      ]
    }
    HingeJoint {
      jointParameters HingeJointParameters {
        anchor -0.05 -0.04 0
      }
      device [
        RotationalMotor {
          name "left wheel motor"
        }
      ]
      endPoint Solid {
        translation -0.05999871797028447 -0.04000398631078779 -5.689806829906218e-06
        rotation -1.4367410358172956e-08 -0.79755697591986 0.6032436242195749 1.2287812309317772e-07
        children [
          DEF WHEEL Transform {
            rotation 0 0 1 1.5707996938995747
            children [
              Shape {
                appearance MattePaint {
                  baseColor 0 0 0
                }
                geometry Cylinder {
                  height 0.02
                  radius 0.02
                  subdivision 24
                }
              }
            ]
          }
        ]
        boundingObject USE WHEEL
        physics Physics {
        }
      }
    }
    HingeJoint {
      jointParameters HingeJointParameters {
        anchor 0.05 -0.04 0
      }
      device [
        RotationalMotor {
          name "right wheel motor"
          acceleration 6
        }
      ]
      endPoint Solid {
        translation 0.06000128181011463 -0.040005032196257666 -4.2246968756644315e-06
        rotation 1 0 0 0
        children [
          DEF WHEEL Transform {
            rotation 0 0 1 1.5707996938995747
            children [
              Shape {
                appearance MattePaint {
                  baseColor 0 0 0
                }
                geometry Cylinder {
                  height 0.02
                  radius 0.02
                  subdivision 24
                }
              }
            ]
          }
        ]
        boundingObject USE WHEEL
        physics Physics {
        }
      }
    }
  ]
  name "Raspi"
  boundingObject USE BODY
  physics Physics {
    density -1
    mass 1
  }
  controller "raspi"
}
Viewpoint {
  orientation -0.13578583223135926 -0.9518503160098609 -0.2748512027937386 2.324202386525184
  position -1.1711807642954004 0.9750788275681976 -1.087944951994123
}
RectangleArena {
  floorAppearance Appearance {
    texture ImageTexture {
      url [
        "C:/Temp/Spielfeld_01.png"
      ]
      repeatS FALSE
      repeatT FALSE
    }
    textureTransform TextureTransform {
      scale 0.5 0.5
    }
  }
  wallAppearance MattePaint {
  }
}
TexturedBackground {
}
