#VRML_SIM R2020a utf8
WorldInfo {
}
Robot {
  translation 0.2 0.06 0.2
  rotation 0.0008188775073231738 0.9999994005189289 0.0007269122443600366 -2.4709203061004255
  children [
    DistanceSensor {
      translation 0 -0.03 0.05
      rotation 0 1 0 -1.5708003061004252
    }
    DEF tLED Transform {
      translation 0 -0.03 0.05
      children [
        LED {
          scale 0.1 0.1 0.1
          children [
            Shape {
              appearance PBRAppearance {
                baseColor 0.8 0.8 0.8
                roughness 0.2
                metalness 0.5
                emissiveIntensity 100
              }
              geometry Box {
                size 0.1 0.1 0.1
              }
            }
          ]
          name "stateled"
          gradual TRUE
        }
      ]
    }
    DEF CAM HingeJoint {
      endPoint Solid {
        rotation 0 1 0 3.141592653589793
        children [
          Transform {
            translation 0 0.01 0
            rotation 1 0 0 -1.5707996938995747
            children [
              Shape {
                appearance MattePaint {
                }
                geometry Cylinder {
                  height 0.03
                  radius 0.01
                }
              }
            ]
          }
          Camera {
            translation 0 0.02 0
            rotation 1 0 0 0
            name "CAM"
          }
        ]
        name "solid(1)"
      }
    }
    DEF BODY Group {
      children [
        DEF markerfix Transform {
          children [
            Shape {
              appearance MattePaint {
                baseColor 0 0 0
              }
              geometry Cylinder {
                height 0.1
                radius 0.01
              }
            }
          ]
        }
        DEF marker Transform {
          translation 0 0.07 0
          children [
            Shape {
              appearance GlossyPaint {
                baseColor 1 0 0.498039
              }
              geometry Cylinder {
                height 0.05
                radius 0.02
              }
            }
          ]
        }
        DEF main Transform {
          translation 0 -0.03 0
          children [
            Shape {
              appearance MattePaint {
                baseColor 0 0 0.498039
              }
              geometry Cylinder {
                height 0.05
                radius 0.05
              }
            }
          ]
        }
        DEF front Transform {
          translation 0 -0.0545 -0.04
          children [
            Shape {
              appearance MattePaint {
                baseColor 0 0 0
              }
              geometry Cylinder {
                height 0.01
                radius 0.01
              }
            }
          ]
        }
        DEF back Transform {
          translation 0 -0.0545 0.04
          children [
            Shape {
              appearance MattePaint {
                baseColor 0 0 0
              }
              geometry Cylinder {
                height 0.01
                radius 0.01
              }
            }
          ]
        }
      ]
    }
    HingeJoint {
      jointParameters HingeJointParameters {
        position 13.805521809375815
        anchor -0.05 -0.04 0
      }
      device [
        RotationalMotor {
          name "left wheel motor"
        }
      ]
      endPoint Solid {
        translation -0.05999871748116081 -0.03999078940089961 9.192342683761226e-06
        rotation 0.9999999999999939 -2.747295907427646e-08 -1.0673372612052652e-07 1.2391510385797218
        children [
          DEF WHEEL Transform {
            rotation 0 0 1 1.5707996938995747
            children [
              Shape {
                appearance MattePaint {
                  baseColor 0 0 0
                }
                geometry Cylinder {
                  height 0.02
                  radius 0.02
                  subdivision 24
                }
              }
            ]
          }
        ]
        boundingObject USE WHEEL
        physics Physics {
        }
      }
    }
    HingeJoint {
      jointParameters HingeJointParameters {
        position 8.205590030515769
        anchor 0.05 -0.04 0
      }
      device [
        RotationalMotor {
          name "right wheel motor"
          acceleration 6
        }
      ]
      endPoint Solid {
        translation 0.06000128159021598 -0.03999967579633158 1.1457914529555335e-05
        rotation -0.9999999999999958 7.491560280225098e-08 -5.2498851638232015e-08 4.360780731855645
        children [
          DEF WHEEL Transform {
            rotation 0 0 1 1.5707996938995747
            children [
              Shape {
                appearance MattePaint {
                  baseColor 0 0 0
                }
                geometry Cylinder {
                  height 0.02
                  radius 0.02
                  subdivision 24
                }
              }
            ]
          }
        ]
        boundingObject USE WHEEL
        physics Physics {
        }
      }
    }
  ]
  name "Raspi"
  boundingObject USE BODY
  physics Physics {
    density -1
    mass 1
  }
  controller "raspi"
}
Robot {
  translation -0.19999995081467623 0.059567161045032485 0.20000004797166018
  rotation -0.001631152029687597 0.999998418034629 0.0007094161653735829 0.8014664186598651
  children [
    DEF CAM HingeJoint {
      endPoint Solid {
        rotation 0 1 0 3.141592653589793
        children [
          DEF LED LED {
            name "LED"
          }
          Transform {
            translation 0 0.01 0
            rotation 1 0 0 -1.5707996938995747
            children [
              Shape {
                appearance MattePaint {
                }
                geometry Cylinder {
                  height 0.03
                  radius 0.01
                }
              }
            ]
          }
          Camera {
            translation 0 0.02 0
            rotation 1 0 0 0
            name "CAM"
          }
        ]
        name "solid(1)"
      }
    }
    DEF BODY Group {
      children [
        DEF markerfix Transform {
          children [
            Shape {
              appearance MattePaint {
                baseColor 0 0 0
              }
              geometry Cylinder {
                height 0.1
                radius 0.01
              }
            }
          ]
        }
        DEF marker Transform {
          translation 0 0.07 0
          children [
            Shape {
              appearance MattePaint {
                baseColor 1 0 0.498039
              }
              geometry Cylinder {
                height 0.05
                radius 0.02
              }
            }
          ]
        }
        DEF main Transform {
          translation 0 -0.03 0
          children [
            Shape {
              appearance MattePaint {
                baseColor 0 0 0.498039
              }
              geometry Cylinder {
                height 0.05
                radius 0.05
              }
            }
          ]
        }
        DEF front Transform {
          translation 0 -0.0545 -0.04
          children [
            Shape {
              appearance MattePaint {
                baseColor 0 0 0
              }
              geometry Cylinder {
                height 0.01
                radius 0.01
              }
            }
          ]
        }
        DEF back Transform {
          translation 0 -0.0545 0.04
          children [
            Shape {
              appearance MattePaint {
                baseColor 0 0 0
              }
              geometry Cylinder {
                height 0.01
                radius 0.01
              }
            }
          ]
        }
      ]
    }
    HingeJoint {
      jointParameters HingeJointParameters {
        position 0.2411202770769236
        anchor -0.05 -0.04 0
      }
      device [
        RotationalMotor {
          name "left wheel motor"
        }
      ]
      endPoint Solid {
        translation -0.05999871748116081 -0.039987282945517316 -2.7587723879391275e-06
        rotation 0.9999999999998584 -3.630939169653707e-07 -3.8901758098588217e-07 0.24112012064003313
        children [
          DEF WHEEL Transform {
            rotation 0 0 1 1.5707996938995747
            children [
              Shape {
                appearance MattePaint {
                  baseColor 0 0 0
                }
                geometry Cylinder {
                  height 0.02
                  radius 0.02
                  subdivision 24
                }
              }
            ]
          }
        ]
        name "solid(2)"
        boundingObject USE WHEEL
        physics Physics {
        }
      }
    }
    HingeJoint {
      jointParameters HingeJointParameters {
        position 0.12901526369244617
        anchor 0.05 -0.04 0
      }
      device [
        RotationalMotor {
          name "right wheel motor"
          acceleration 6
        }
      ]
      endPoint Solid {
        translation 0.06000128159021598 -0.03998889634308481 -2.845648694922098e-06
        rotation 0.999999999999296 -7.453284575873237e-08 1.18419328486156e-06 0.12901511274907546
        children [
          DEF WHEEL Transform {
            rotation 0 0 1 1.5707996938995747
            children [
              Shape {
                appearance MattePaint {
                  baseColor 0 0 0
                }
                geometry Cylinder {
                  height 0.02
                  radius 0.02
                  subdivision 24
                }
              }
            ]
          }
        ]
        boundingObject USE WHEEL
        physics Physics {
        }
      }
    }
  ]
  name "Raspi(1)"
  boundingObject USE BODY
  physics Physics {
    density -1
    mass 1
  }
  controller ""
}
Viewpoint {
  orientation 0.010423416614763698 -0.9661547850775458 -0.2577523688694955 3.14162740537985
  position 0.19426912575923683 0.7212787361873199 -1.1242858163841385
}
RectangleArena {
  floorAppearance Appearance {
    texture ImageTexture {
      url [
        "C:/Temp/Spielfeld_01.png"
      ]
      repeatS FALSE
      repeatT FALSE
    }
    textureTransform TextureTransform {
      scale 0.5 0.5
    }
  }
  wallAppearance MattePaint {
  }
}
TexturedBackground {
}
